Workbook

Sheet MasterSheet_WithPredictive
A1: KEY | B1: Country | C1: Year | D1: Global GDP | E1: Global_GDP_Growth | F1: Global Population | G1: Global_Population_Growth | H1: GDP | I1: GDP_Growth_Rate | J1: Country Population | K1: Country Population_Rate | L1: Global GDP % | M1: Import | N1: Export | O1: Trade Balance | P1: Trade Balance to GDP | Q1: Debt to GDP | R1: Debt_to_GDP_Growth | S1: Debt | T1: Interest | U1: Interest Payment | V1: Interest Payment to GDP | W1: Inflation | X1: PCI | Y1: Adjusted PCI | Z1: HDI | AA1: HDI_Growth | AB1: Ginni | AC1: Ginni_Growth | AD1: Adjusted HDI | AE1: Housing | AF1: Health | AG1: Energy | AH1: Education | AI1: Scio-Economic | AJ1: Heart Value | AK1: Heart Affordibility Value | AL1: Affordbility Ranking | AM1: Heart Score | AN1: Brief Description of HEART Scores | AO1: Brief Description of HEART Scores by Mr. Khurshid | AP1: Assumption
A2: =_xlfn.CONCAT(UPPER(B2),"|",C2) -> INDIA|2019 | B2: India | C2: 2019 | D2: 87700000000000 | F2: 7810000000 | H2: 2840000000000 | J2: 1390000000 | L2: 0.032383124 | M2: 632000000000 | N2: 538000000000 | O2: -94000000000 | P2: -0.033098592 | Q2: 0.75 | S2: 2130000000000 | T2: 0.0625 | U2: 133125000000 | V2: 0.046875 | W2: 0.0373 | X2: 2043.1655 | Y2: 1966.9554 | Z2: 0.651 | AB2: 0.338 | AD2: 0.313 | AE2: 0.06668832 | AF2: 0.011688304 | AG2: 0.036688203 | AH2: 0.032688219 | AI2: 0.14775305 | AJ2: 0.10016258 | AK2: 615.65704 | AL2: D- | AM2: 0.1D- | AN2: =_xlfn.CONCAT(_xlfn.IFS( AJ2>=0.7,"Superb", AJ2>=0.51,"Excellent", AJ2>=0.41,"Good", AJ2>=0.31,"Satisfactory", AJ2>=0.26,"Moderate", AJ2>=0.1,"Weak", AJ2<0.1,"Very Weak" ), " Economic Resilience with ",_xlfn.IFS( AK2<=2500,"Very Weak", AK2<=5000,"Poor", AK2<=10000,"Challenging", AK2<=12500,"Border Line", AK2<=15000,"Improved", AK2<=20000,"Moderate", AK2<=25000,"Satisfactory", AK2<=30000,"Good", AK2<=35000,"Very Good", AK2<=40000,"High", AK2<=50000,"Excellent", AK2<=100000,"Superb", AK2>100000,"Superb" ), " Affordability.") -> Weak Economic Resilience with Very Weak Affordability. | AP2: We will assume the 5 socio economic sector spending will increase by 5% every year, Socio Ecnomic Sectors are Health, Housing, Energy and Education. Based on this assumption we will predict the value of Heart next year
A3: =_xlfn.CONCAT(UPPER(B3),"|",C3) -> INDIA|2020 | B3: India | C3: 2020 | D3: 84750000000000 | E3: -0.0336374 | F3: 7890000000 | G3: 0.010243278 | H3: 2670000000000 | I3: -0.059859155 | J3: 1400000000 | K3: 0.0071942446 | L3: 0.031504425 | M3: 546000000000 | N3: 497000000000 | O3: -49000000000 | P3: -0.01835206 | Q3: 0.884 | R3: 0.17866667 | S3: 2360280000000 | T3: 0.044 | U3: 103852320000 | V3: 0.038896 | W3: 0.0662 | X3: 1907.1429 | Y3: 1780.89 | Z3: 0.652 | AA3: 0.0015360983 | AB3: 0.338 | AC3: 0 | AD3: 0.314 | AE3: 0.068632439 | AF3: 0.013632423 | AG3: 0.038632322 | AH3: 0.034632338 | AI3: 0.15552952 | AJ3: 0.12978589 | AK3: 559.19946 | AL3: D- | AM3: 0.13D- | AN3: =_xlfn.CONCAT(_xlfn.IFS( AJ3>=0.7,"Superb", AJ3>=0.51,"Excellent", AJ3>=0.41,"Good", AJ3>=0.31,"Satisfactory", AJ3>=0.26,"Moderate", AJ3>=0.1,"Weak", AJ3<0.1,"Very Weak" ), " Economic Resilience with ",_xlfn.IFS( AK3<=2500,"Very Weak", AK3<=5000,"Poor", AK3<=10000,"Challenging", AK3<=12500,"Border Line", AK3<=15000,"Improved", AK3<=20000,"Moderate", AK3<=25000,"Satisfactory", AK3<=30000,"Good", AK3<=35000,"Very Good", AK3<=40000,"High", AK3<=50000,"Excellent", AK3<=100000,"Superb", AK3>100000,"Superb" ), " Affordability.") -> Weak Economic Resilience with Very Weak Affordability. | AP3: We will assume the 5 socio economic sector spending will increase by 5% every year, Socio Ecnomic Sectors are Health, Housing, Energy and Education. Based on this assumption we will predict the value of Heart next year
A4: =_xlfn.CONCAT(UPPER(B4),"|",C4) -> INDIA|2021 | B4: India | C4: 2021 | D4: 96140000000000 | E4: 0.13439528 | F4: 7950000000 | G4: 0.0076045627 | H4: 3170000000000 | I4: 0.18726592 | J4: 1410000000 | K4: 0.0071428571 | L4: 0.032972748 | M4: 670000000000 | N4: 612000000000 | O4: -58000000000 | P4: -0.01829653 | Q4: 0.835 | R4: -0.055429864 | S4: 2646950000000 | T4: 0.04 | U4: 105878000000 | V4: 0.0334 | W4: 0.0513 | X4: 2248.227 | Y4: 2132.8929 | Z4: 0.647 | AA4: -0.0076687117 | AB4: 0.328 | AC4: -0.030487805 | AD4: 0.319 | AE4: 0.07067888 | AF4: 0.015678864 | AG4: 0.040678763 | AH4: 0.036678779 | AI4: 0.16371529 | AJ4: 0.1449915 | AK4: 680.39284 | AL4: D- | AM4: 0.14D- | AN4: =_xlfn.CONCAT(_xlfn.IFS( AJ4>=0.7,"Superb", AJ4>=0.51,"Excellent", AJ4>=0.41,"Good", AJ4>=0.31,"Satisfactory", AJ4>=0.26,"Moderate", AJ4>=0.1,"Weak", AJ4<0.1,"Very Weak" ), " Economic Resilience with ",_xlfn.IFS( AK4<=2500,"Very Weak", AK4<=5000,"Poor", AK4<=10000,"Challenging", AK4<=12500,"Border Line", AK4<=15000,"Improved", AK4<=20000,"Moderate", AK4<=25000,"Satisfactory", AK4<=30000,"Good", AK4<=35000,"Very Good", AK4<=40000,"High", AK4<=50000,"Excellent", AK4<=100000,"Superb", AK4>100000,"Superb" ), " Affordability.") -> Weak Economic Resilience with Very Weak Affordability. | AP4: We will assume the 5 socio economic sector spending will increase by 5% every year, Socio Ecnomic Sectors are Health, Housing, Energy and Education. Based on this assumption we will predict the value of Heart next year
A5: =_xlfn.CONCAT(UPPER(B5),"|",C5) -> INDIA|2022 | B5: India | C5: 2022 | D5: 101560000000000 | E5: 0.056376118 | F5: 8020000000 | G5: 0.0088050314 | H5: 3350000000000 | I5: 0.056782334 | J5: 1430000000 | K5: 0.014184397 | L5: 0.032985427 | M5: 788000000000 | N5: 743000000000 | O5: -45000000000 | P5: -0.013432836 | Q5: 0.822 | R5: -0.015568862 | S5: 2753700000000 | T5: 0.04 | U5: 110148000000 | V5: 0.03288 | W5: 0.067 | X5: 2342.6573 | Y5: 2185.6993 | Z5: 0.676 | AA5: 0.044822257 | AB5: 0.328 | AC5: 0 | AD5: 0.348 | AE5: 0.072833028 | AF5: 0.017833013 | AG5: 0.042832911 | AH5: 0.038832928 | AI5: 0.17233188 | AJ5: 0.15900447 | AK5: 760.62336 | AL5: D- | AM5: 0.16D- | AN5: =_xlfn.CONCAT(_xlfn.IFS( AJ5>=0.7,"Superb", AJ5>=0.51,"Excellent", AJ5>=0.41,"Good", AJ5>=0.31,"Satisfactory", AJ5>=0.26,"Moderate", AJ5>=0.1,"Weak", AJ5<0.1,"Very Weak" ), " Economic Resilience with ",_xlfn.IFS( AK5<=2500,"Very Weak", AK5<=5000,"Poor", AK5<=10000,"Challenging", AK5<=12500,"Border Line", AK5<=15000,"Improved", AK5<=20000,"Moderate", AK5<=25000,"Satisfactory", AK5<=30000,"Good", AK5<=35000,"Very Good", AK5<=40000,"High", AK5<=50000,"Excellent", AK5<=100000,"Superb", AK5>100000,"Superb" ), " Affordability.") -> Weak Economic Resilience with Very Weak Affordability. | AP5: We will assume the 5 socio economic sector spending will increase by 5% every year, Socio Ecnomic Sectors are Health, Housing, Energy and Education. Based on this assumption we will predict the value of Heart next year
A6: =_xlfn.CONCAT(UPPER(B6),"|",C6) -> INDIA|2023 | B6: India | C6: 2023 | D6: 106800000000000 | E6: 0.051595116 | F6: 8090000000 | G6: 0.0087281796 | H6: 3640000000000 | I6: 0.086567164 | J6: 1440000000 | K6: 0.006993007 | L6: 0.034082397 | M6: 856650000000 | N6: 774000000000 | O6: -82650000000 | P6: -0.022706044 | Q6: 0.812 | R6: -0.01216545 | S6: 2955680000000 | T6: 0.065 | U6: 192119200000 | V6: 0.05278 | W6: 0.0565 | X6: 2527.7778 | Y6: 2384.9583 | Z6: 0.685 | AA6: 0.013313609 | AB6: 0.328 | AC6: 0 | AD6: 0.357 | AE6: 0.075100553 | AF6: 0.020100538 | AG6: 0.045100436 | AH6: 0.041100452 | AI6: 0.18140198 | AJ6: 0.13999833 | AK6: 851.43012 | AL6: D- | AM6: 0.14D- | AN6: =_xlfn.CONCAT(_xlfn.IFS( AJ6>=0.7,"Superb", AJ6>=0.51,"Excellent", AJ6>=0.41,"Good", AJ6>=0.31,"Satisfactory", AJ6>=0.26,"Moderate", AJ6>=0.1,"Weak", AJ6<0.1,"Very Weak" ), " Economic Resilience with ",_xlfn.IFS( AK6<=2500,"Very Weak", AK6<=5000,"Poor", AK6<=10000,"Challenging", AK6<=12500,"Border Line", AK6<=15000,"Improved", AK6<=20000,"Moderate", AK6<=25000,"Satisfactory", AK6<=30000,"Good", AK6<=35000,"Very Good", AK6<=40000,"High", AK6<=50000,"Excellent", AK6<=100000,"Superb", AK6>100000,"Superb" ), " Affordability.") -> Weak Economic Resilience with Very Weak Affordability. | AP6: We will assume the 5 socio economic sector spending will increase by 5% every year, Socio Ecnomic Sectors are Health, Housing, Energy and Education. Based on this assumption we will predict the value of Heart next year
A7: =_xlfn.CONCAT(UPPER(B7),"|",C7) -> INDIA|2024 | B7: India | C7: 2024 | D7: 112600000000000 | E7: 0.054307116 | F7: 8161972572 | G7: 0.008896486 | H7: 3910000000000 | I7: 0.074175824 | J7: 1450000000 | K7: 0.0069444444 | L7: 0.034724689 | M7: 919210000000 | N7: 828630000000 | O7: -90580000000 | P7: -0.02316624 | Q7: 0.813 | R7: 0.0012315271 | S7: 3178830000000 | T7: 0.065 | U7: 206623950000 | V7: 0.052845 | W7: 0.0495 | X7: 2696.5517 | Y7: 2563.0724 | Z7: 0.685 | AA7: 0 | AB7: 0.328 | AC7: 0 | AD7: 0.357 | AE7: 0.077487421 | AF7: 0.022487406 | AG7: 0.047487304 | AH7: 0.04348732 | AI7: 0.19094945 | AJ7: 0.1496629 | AK7: 915.01685 | AL7: D- | AM7: 0.15D- | AN7: =_xlfn.CONCAT(_xlfn.IFS( AJ7>=0.7,"Superb", AJ7>=0.51,"Excellent", AJ7>=0.41,"Good", AJ7>=0.31,"Satisfactory", AJ7>=0.26,"Moderate", AJ7>=0.1,"Weak", AJ7<0.1,"Very Weak" ), " Economic Resilience with ",_xlfn.IFS( AK7<=2500,"Very Weak", AK7<=5000,"Poor", AK7<=10000,"Challenging", AK7<=12500,"Border Line", AK7<=15000,"Improved", AK7<=20000,"Moderate", AK7<=25000,"Satisfactory", AK7<=30000,"Good", AK7<=35000,"Very Good", AK7<=40000,"High", AK7<=50000,"Excellent", AK7<=100000,"Superb", AK7>100000,"Superb" ), " Affordability.") -> Weak Economic Resilience with Very Weak Affordability. | AP7: We will assume the 5 socio economic sector spending will increase by 5% every year, Socio Ecnomic Sectors are Health, Housing, Energy and Education. Based on this assumption we will predict the value of Heart next year
A8: =_xlfn.CONCAT(UPPER(B8),"|",C8) -> INDIA|2025 | B8: India | C8: 2025 | D8: 113795678000000 | E8: 0.01061881 | F8: 8231613070 | G8: 0.0085323122 | H8: 4187017000000 | I8: 0.070848338 | J8: 1425000000 | K8: -0.017241379 | L8: 0.036794165 | M8: 918920000000 | N8: 828920000000 | O8: -90000000000 | P8: -0.021495017 | Q8: 0.82999997 | R8: 0.020910177 | S8: 3475224000000 | T8: 0.055 | U8: 191137320000 | V8: 0.045649999 | W8: 0.0282 | X8: 2938.2575 | Y8: 2855.3987 | Z8: 0.685 | AA8: 0 | AB8: 0.328 | AC8: 0 | AD8: 0.357 | AE8: 0.079999914 | AF8: 0.024999898 | AG8: 0.049999797 | AH8: 0.045999813 | AI8: 0.20099942 | AJ8: 0.17064857 | AK8: 1019.3773 | AL8: D- | AM8: 0.17D- | AN8: =_xlfn.CONCAT(_xlfn.IFS( AJ8>=0.7,"Superb", AJ8>=0.51,"Excellent", AJ8>=0.41,"Good", AJ8>=0.31,"Satisfactory", AJ8>=0.26,"Moderate", AJ8>=0.1,"Weak", AJ8<0.1,"Very Weak" ), " Economic Resilience with ",_xlfn.IFS( AK8<=2500,"Very Weak", AK8<=5000,"Poor", AK8<=10000,"Challenging", AK8<=12500,"Border Line", AK8<=15000,"Improved", AK8<=20000,"Moderate", AK8<=25000,"Satisfactory", AK8<=30000,"Good", AK8<=35000,"Very Good", AK8<=40000,"High", AK8<=50000,"Excellent", AK8<=100000,"Superb", AK8>100000,"Superb" ), " Affordability.") -> Weak Economic Resilience with Very Weak Affordability. | AO8: 4th largest per GDP but underperformed against peer China.Very low Affordability and Human development. Must adopt inclussive economy & fix US tarrif threat. | AP8: We will assume the 5 socio economic sector spending will increase by 5% every year, Socio Ecnomic Sectors are Health, Housing, Energy and Education. Based on this assumption we will predict the value of Heart next year
A9: =_xlfn.CONCAT(UPPER(B9),"|",C9) -> INDIA|2026 | B9: India | C9: 2026 | D9: 120063810405112 | E9: 0.055082342 | F9: 8302201675 | G9: 0.0085753064 | H9: 4435586665427 | I9: 0.059366768 | J9: 1442637444 | K9: 0.012377153 | L9: 0.036943577 | M9: 1017801428571 | N9: 931367142857 | O9: -86434285714 | P9: -0.019486551 | Q9: 0.83892275 | R9: 0.010750333 | S9: 3721114563803 | T9: 0.059428571 | U9: 221140522649 | V9: 0.049855981 | W9: 0.042928571 | X9: 3074.6371 | Y9: 2942.6474 | Z9: 0.69453995 | AA9: 0.013926931 | AB9: 0.32502381 | AC9: -0.0091568383 | AD9: 0.36951614 | AE9: 0.082512407 | AF9: 0.027512391 | AG9: 0.05251229 | AH9: 0.048512306 | AI9: 0.21104939 | AJ9: 0.17865044 | AK9: 1087.3557 | AL9: D- | AM9: 0.18D- | AN9: =_xlfn.CONCAT(_xlfn.IFS( AJ9>=0.7,"Superb", AJ9>=0.51,"Excellent", AJ9>=0.41,"Good", AJ9>=0.31,"Satisfactory", AJ9>=0.26,"Moderate", AJ9>=0.1,"Weak", AJ9<0.1,"Very Weak" ), " Economic Resilience with ",_xlfn.IFS( AK9<=2500,"Very Weak", AK9<=5000,"Poor", AK9<=10000,"Challenging", AK9<=12500,"Border Line", AK9<=15000,"Improved", AK9<=20000,"Moderate", AK9<=25000,"Satisfactory", AK9<=30000,"Good", AK9<=35000,"Very Good", AK9<=40000,"High", AK9<=50000,"Excellent", AK9<=100000,"Superb", AK9>100000,"Superb" ), " Affordability.") -> Weak Economic Resilience with Very Weak Affordability. | AP9: We will assume the 5 socio economic sector spending will increase by 5% every year, Socio Ecnomic Sectors are Health, Housing, Energy and Education. Based on this assumption we will predict the value of Heart next year
A10: =_xlfn.CONCAT(UPPER(B10),"|",C10) -> INDIA|2027 | B10: India | C10: 2027 | D10: 125735541889780 | E10: 0.047239309 | F10: 8372937901 | G10: 0.0085201769 | H10: 4700572377145 | I10: 0.059740849 | J10: 1453619908 | K10: 0.0076127683 | L10: 0.037384596 | M10: 1081866785714 | N10: 992010714286 | O10: -89856071429 | P10: -0.019115985 | Q10: 0.84611799 | R10: 0.0085767638 | S10: 3977238863025 | T10: 0.061017857 | U10: 242682592767 | V10: 0.051628307 | W10: 0.040946429 | X10: 3233.7012 | Y10: 3101.2926 | Z10: 0.70239004 | AA10: 0.011302582 | AB10: 0.32288318 | AC10: -0.0066297278 | AD10: 0.37950686 | AE10: 0.085150524 | AF10: 0.030150509 | AG10: 0.055150407 | AH10: 0.051150423 | AI10: 0.22160186 | AJ10: 0.18824217 | AK10: 1176.9618 | AL10: D- | AM10: 0.19D- | AN10: =_xlfn.CONCAT(_xlfn.IFS( AJ10>=0.7,"Superb", AJ10>=0.51,"Excellent", AJ10>=0.41,"Good", AJ10>=0.31,"Satisfactory", AJ10>=0.26,"Moderate", AJ10>=0.1,"Weak", AJ10<0.1,"Very Weak" ), " Economic Resilience with ",_xlfn.IFS( AK10<=2500,"Very Weak", AK10<=5000,"Poor", AK10<=10000,"Challenging", AK10<=12500,"Border Line", AK10<=15000,"Improved", AK10<=20000,"Moderate", AK10<=25000,"Satisfactory", AK10<=30000,"Good", AK10<=35000,"Very Good", AK10<=40000,"High", AK10<=50000,"Excellent", AK10<=100000,"Superb", AK10>100000,"Superb" ), " Affordability.") -> Weak Economic Resilience with Very Weak Affordability. | AP10: We will assume the 5 socio economic sector spending will increase by 5% every year, Socio Ecnomic Sectors are Health, Housing, Energy and Education. Based on this assumption we will predict the value of Heart next year
A11: =_xlfn.CONCAT(UPPER(B11),"|",C11) -> INDIA|2028 | B11: India | C11: 2028 | D11: 131237442252096 | E11: 0.043757718 | F11: 8443822776 | G11: 0.0084659502 | H11: 4974261388939 | I11: 0.058224614 | J11: 1462336629 | K11: 0.0059965613 | L11: 0.037902761 | M11: 1145932142857 | N11: 1052654285714 | O11: -93277857143 | P11: -0.018752102 | Q11: 0.8527313 | R11: 0.0078160571 | S11: 4241708375729 | T11: 0.062607143 | U11: 265561242238 | V11: 0.05338707 | W11: 0.038964286 | X11: 3401.5843 | Y11: 3269.044 | Z11: 0.70967244 | AA11: 0.010368019 | AB11: 0.32102777 | AC11: -0.0057795964 | AD11: 0.38864467 | AE11: 0.087920548 | AF11: 0.032920532 | AG11: 0.05792043 | AH11: 0.053920447 | AI11: 0.23268196 | AJ11: 0.19844555 | AK11: 1270.4965 | AL11: D- | AM11: 0.2D- | AN11: =_xlfn.CONCAT(_xlfn.IFS( AJ11>=0.7,"Superb", AJ11>=0.51,"Excellent", AJ11>=0.41,"Good", AJ11>=0.31,"Satisfactory", AJ11>=0.26,"Moderate", AJ11>=0.1,"Weak", AJ11<0.1,"Very Weak" ), " Economic Resilience with ",_xlfn.IFS( AK11<=2500,"Very Weak", AK11<=5000,"Poor", AK11<=10000,"Challenging", AK11<=12500,"Border Line", AK11<=15000,"Improved", AK11<=20000,"Moderate", AK11<=25000,"Satisfactory", AK11<=30000,"Good", AK11<=35000,"Very Good", AK11<=40000,"High", AK11<=50000,"Excellent", AK11<=100000,"Superb", AK11>100000,"Superb" ), " Affordability.") -> Weak Economic Resilience with Very Weak Affordability. | AP11: We will assume the 5 socio economic sector spending will increase by 5% every year, Socio Ecnomic Sectors are Health, Housing, Energy and Education. Based on this assumption we will predict the value of Heart next year
A12: =_xlfn.CONCAT(UPPER(B12),"|",C12) -> INDIA|2029 | B12: India | C12: 2029 | D12: 136712479650225 | E12: 0.041718562 | F12: 8514849364 | G12: 0.0084116625 | H12: 5253763699966 | I12: 0.056189711 | J12: 1470250482 | K12: 0.0054117861 | L12: 0.038429291 | M12: 1209997500000 | N12: 1113297857143 | O12: -96699642857 | P12: -0.018405785 | Q12: 0.85914709 | R12: 0.007523812 | S12: 4513755788876 | T12: 0.064196429 | U12: 289767001089 | V12: 0.055154175 | W12: 0.036982143 | X12: 3573.38 | Y12: 3441.2288 | Z12: 0.71676148 | AA12: 0.0099891712 | AB12: 0.31927477 | AC12: -0.0054905762 | AD12: 0.39748671 | AE12: 0.090829072 | AF12: 0.035829056 | AG12: 0.060828955 | AH12: 0.056828971 | AI12: 0.24431605 | AJ12: 0.20918539 | AK12: 1367.8427 | AL12: D- | AM12: 0.21D- | AN12: =_xlfn.CONCAT(_xlfn.IFS( AJ12>=0.7,"Superb", AJ12>=0.51,"Excellent", AJ12>=0.41,"Good", AJ12>=0.31,"Satisfactory", AJ12>=0.26,"Moderate", AJ12>=0.1,"Weak", AJ12<0.1,"Very Weak" ), " Economic Resilience with ",_xlfn.IFS( AK12<=2500,"Very Weak", AK12<=5000,"Poor", AK12<=10000,"Challenging", AK12<=12500,"Border Line", AK12<=15000,"Improved", AK12<=20000,"Moderate", AK12<=25000,"Satisfactory", AK12<=30000,"Good", AK12<=35000,"Very Good", AK12<=40000,"High", AK12<=50000,"Excellent", AK12<=100000,"Superb", AK12>100000,"Superb" ), " Affordability.") -> Weak Economic Resilience with Very Weak Affordability. | AP12: We will assume the 5 socio economic sector spending will increase by 5% every year, Socio Ecnomic Sectors are Health, Housing, Energy and Education. Based on this assumption we will predict the value of Heart next year
A13: =_xlfn.CONCAT(UPPER(B13),"|",C13) -> INDIA|2030 | B13: India | C13: 2030 | D13: 142137128357288 | F13: 8586617399 | H13: 5548925439435 | J13: 1475246999 | L13: 0.03903924 | M13: 1274062857143 | N13: 1173941428571 | O13: -100121428571 | P13: -0.01804339 | Q13: 0.86549985 | S13: 4802594109468 | T13: 0.065785714 | U13: 315942083916 | V13: 0.056937526 | W13: 0.035 | X13: 3761.3535 | Y13: 3629.7061 | Z13: 0.72378782 | AB13: 0.31756052 | AD13: 0.4062273 | AE13: 0.093883023 | AF13: 0.038883007 | AG13: 0.063882906 | AH13: 0.059882922 | AI13: 0.25653186 | AJ13: 0.22059018 | AK13: 1474.4857 | AL13: D- | AM13: 0.22D- | AN13: =_xlfn.CONCAT(_xlfn.IFS( AJ13>=0.7,"Superb", AJ13>=0.51,"Excellent", AJ13>=0.41,"Good", AJ13>=0.31,"Satisfactory", AJ13>=0.26,"Moderate", AJ13>=0.1,"Weak", AJ13<0.1,"Very Weak" ), " Economic Resilience with ",_xlfn.IFS( AK13<=2500,"Very Weak", AK13<=5000,"Poor", AK13<=10000,"Challenging", AK13<=12500,"Border Line", AK13<=15000,"Improved", AK13<=20000,"Moderate", AK13<=25000,"Satisfactory", AK13<=30000,"Good", AK13<=35000,"Very Good", AK13<=40000,"High", AK13<=50000,"Excellent", AK13<=100000,"Superb", AK13>100000,"Superb" ), " Affordability.") -> Weak Economic Resilience with Very Weak Affordability. | AP13: We will assume the 5 socio economic sector spending will increase by 5% every year, Socio Ecnomic Sectors are Health, Housing, Energy and Education. Based on this assumption we will predict the value of Heart next year
A14: =_xlfn.CONCAT(UPPER(B14),"|",C14) -> USA|2019 | B14: USA | C14: 2019 | D14: 87700000000000 | F14: 7810000000 | H14: 21540000000000 | J14: 330226227 | L14: 0.24561003 | M14: 2512360000000 | N14: 1655100000000 | O14: -857260000000 | P14: -0.039798514 | Q14: 1.054754 | S14: 22719401753434 | T14: 0.0225 | U14: 511186539452 | V14: 0.023731966 | W14: 0.02 | X14: 65228.011 | Y14: 63923.451 | Z14: 0.936 | AB14: 0.419 | AD14: 0.517 | AE14: 0.12978058 | AF14: 0.14478058 | AG14: 0.048780579 | AH14: 0.023180579 | AI14: 0.34652232 | AJ14: 0.52860187 | AK14: 33048.424 | AL14: B+ | AM14: 0.53B+ | AN14: =_xlfn.CONCAT(_xlfn.IFS( AJ14>=0.7,"Superb", AJ14>=0.51,"Excellent", AJ14>=0.41,"Good", AJ14>=0.31,"Satisfactory", AJ14>=0.26,"Moderate", AJ14>=0.1,"Weak", AJ14<0.1,"Very Weak" ), " Economic Resilience with ",_xlfn.IFS( AK14<=2500,"Very Weak", AK14<=5000,"Poor", AK14<=10000,"Challenging", AK14<=12500,"Border Line", AK14<=15000,"Improved", AK14<=20000,"Moderate", AK14<=25000,"Satisfactory", AK14<=30000,"Good", AK14<=35000,"Very Good", AK14<=40000,"High", AK14<=50000,"Excellent", AK14<=100000,"Superb", AK14>100000,"Superb" ), " Affordability.") -> Excellent Economic Resilience with Very Good Affordability. | AP14: We will assume the 5 socio economic sector spending will increase by 5% every year, Socio Ecnomic Sectors are Health, Housing, Energy and Education. Based on this assumption we will predict the value of Heart next year
A15: =_xlfn.CONCAT(UPPER(B15),"|",C15) -> USA|2020 | B15: USA | C15: 2020 | D15: 84750000000000 | E15: -0.0336374 | F15: 7890000000 | G15: 0.010243278 | H15: 21350000000000 | I15: -0.0088207985 | J15: 331577720 | K15: 0.0040926277 | L15: 0.2519174 | M15: 2346730000000 | N15: 1433850000000 | O15: -912880000000 | P15: -0.042757845 | Q15: 1.2620792 | R15: 0.19656259 | S15: 26945391194615 | T15: 0.0025 | U15: 67363477987 | V15: 0.003155198 | W15: 0.003 | X15: 64389.127 | Y15: 64195.96 | Z15: 0.925 | AA15: -0.011752137 | AB15: 0.4 | AC15: -0.0475 | AD15: 0.525 | AE15: 0.13434008 | AF15: 0.14934008 | AG15: 0.053340083 | AH15: 0.027740083 | AI15: 0.36476033 | AJ15: 0.57076469 | AK15: 33702.879 | AL15: B+ | AM15: 0.57B+ | AN15: =_xlfn.CONCAT(_xlfn.IFS( AJ15>=0.7,"Superb", AJ15>=0.51,"Excellent", AJ15>=0.41,"Good", AJ15>=0.31,"Satisfactory", AJ15>=0.26,"Moderate", AJ15>=0.1,"Weak", AJ15<0.1,"Very Weak" ), " Economic Resilience with ",_xlfn.IFS( AK15<=2500,"Very Weak", AK15<=5000,"Poor", AK15<=10000,"Challenging", AK15<=12500,"Border Line", AK15<=15000,"Improved", AK15<=20000,"Moderate", AK15<=25000,"Satisfactory", AK15<=30000,"Good", AK15<=35000,"Very Good", AK15<=40000,"High", AK15<=50000,"Excellent", AK15<=100000,"Superb", AK15>100000,"Superb" ), " Affordability.") -> Excellent Economic Resilience with Very Good Affordability. | AP15: We will assume the 5 socio economic sector spending will increase by 5% every year, Socio Ecnomic Sectors are Health, Housing, Energy and Education. Based on this assumption we will predict the value of Heart next year
A16: =_xlfn.CONCAT(UPPER(B16),"|",C16) -> USA|2021 | B16: USA | C16: 2021 | D16: 96140000000000 | E16: 0.13439528 | F16: 7950000000 | G16: 0.0076045627 | H16: 23680000000000 | I16: 0.10913349 | J16: 332099760 | K16: 0.0015744122 | L16: 0.24630747 | M16: 2849040000000 | N16: 1765850000000 | O16: -1083190000000 | P16: -0.045742821 | Q16: 1.2005455 | R16: -0.048755787 | S16: 2.8428919e+13 | T16: 0.0025 | U16: 71072296425 | V16: 0.0030013639 | W16: 0.042 | X16: 71303.876 | Y16: 68309.113 | Z16: 0.921 | AA16: -0.0043243243 | AB16: 0.397 | AC16: -0.0075566751 | AD16: 0.524 | AE16: 0.13913956 | AF16: 0.15413956 | AG16: 0.058139562 | AH16: 0.032539562 | AI16: 0.38395825 | AJ16: 0.58152153 | AK16: 35793.975 | AL16: A- | AM16: 0.58A- | AN16: =_xlfn.CONCAT(_xlfn.IFS( AJ16>=0.7,"Superb", AJ16>=0.51,"Excellent", AJ16>=0.41,"Good", AJ16>=0.31,"Satisfactory", AJ16>=0.26,"Moderate", AJ16>=0.1,"Weak", AJ16<0.1,"Very Weak" ), " Economic Resilience with ",_xlfn.IFS( AK16<=2500,"Very Weak", AK16<=5000,"Poor", AK16<=10000,"Challenging", AK16<=12500,"Border Line", AK16<=15000,"Improved", AK16<=20000,"Moderate", AK16<=25000,"Satisfactory", AK16<=30000,"Good", AK16<=35000,"Very Good", AK16<=40000,"High", AK16<=50000,"Excellent", AK16<=100000,"Superb", AK16>100000,"Superb" ), " Affordability.") -> Excellent Economic Resilience with High Affordability. | AP16: We will assume the 5 socio economic sector spending will increase by 5% every year, Socio Ecnomic Sectors are Health, Housing, Energy and Education. Based on this assumption we will predict the value of Heart next year
A17: =_xlfn.CONCAT(UPPER(B17),"|",C17) -> USA|2022 | B17: USA | C17: 2022 | D17: 101560000000000 | E17: 0.056376118 | F17: 8020000000 | G17: 0.0088050314 | H17: 26010000000000 | I17: 0.09839527 | J17: 334017321 | K17: 0.0057740511 | L17: 0.25610477 | M17: 3270280000000 | N17: 2090340000000 | O17: -1179940000000 | P17: -0.04536486 | Q17: 1.1891162 | R17: -0.0095201523 | S17: 30928911613307 | T17: 0.025 | U17: 773222790333 | V17: 0.029727904 | W17: 0.083 | X17: 77870.213 | Y17: 71406.986 | Z17: 0.93 | AA17: 0.009771987 | AB17: 0.417 | AC17: 0.047961631 | AD17: 0.513 | AE17: 0.14419164 | AF17: 0.15919164 | AG17: 0.063191644 | AH17: 0.037591644 | AI17: 0.40416657 | AJ17: 0.58517858 | AK17: 36631.784 | AL17: A- | AM17: 0.59A- | AN17: =_xlfn.CONCAT(_xlfn.IFS( AJ17>=0.7,"Superb", AJ17>=0.51,"Excellent", AJ17>=0.41,"Good", AJ17>=0.31,"Satisfactory", AJ17>=0.26,"Moderate", AJ17>=0.1,"Weak", AJ17<0.1,"Very Weak" ), " Economic Resilience with ",_xlfn.IFS( AK17<=2500,"Very Weak", AK17<=5000,"Poor", AK17<=10000,"Challenging", AK17<=12500,"Border Line", AK17<=15000,"Improved", AK17<=20000,"Moderate", AK17<=25000,"Satisfactory", AK17<=30000,"Good", AK17<=35000,"Very Good", AK17<=40000,"High", AK17<=50000,"Excellent", AK17<=100000,"Superb", AK17>100000,"Superb" ), " Affordability.") -> Excellent Economic Resilience with High Affordability. | AP17: We will assume the 5 socio economic sector spending will increase by 5% every year, Socio Ecnomic Sectors are Health, Housing, Energy and Education. Based on this assumption we will predict the value of Heart next year
A18: =_xlfn.CONCAT(UPPER(B18),"|",C18) -> USA|2023 | B18: USA | C18: 2023 | D18: 106800000000000 | E18: 0.051595116 | F18: 8090000000 | G18: 0.0087281796 | H18: 27720000000000 | I18: 0.065743945 | J18: 336806231 | K18: 0.0083495969 | L18: 0.25955056 | M18: 3108510000000 | N18: 2045220000000 | O18: -1063290000000 | P18: -0.038358225 | Q18: 1.1965128 | R18: 0.0062202509 | S18: 33167334044723 | T18: 0.055 | U18: 1824203372460 | V18: 0.065808202 | W18: 0.049 | X18: 82302.515 | Y18: 78269.692 | Z18: 0.938 | AA18: 0.0086021505 | AB18: 0.418 | AC18: 0.0023923445 | AD18: 0.52 | AE18: 0.14950963 | AF18: 0.16450962 | AG18: 0.068509625 | AH18: 0.042909625 | AI18: 0.4254385 | AJ18: 0.58082263 | AK18: 40700.24 | AL18: A | AM18: 0.58A | AN18: =_xlfn.CONCAT(_xlfn.IFS( AJ18>=0.7,"Superb", AJ18>=0.51,"Excellent", AJ18>=0.41,"Good", AJ18>=0.31,"Satisfactory", AJ18>=0.26,"Moderate", AJ18>=0.1,"Weak", AJ18<0.1,"Very Weak" ), " Economic Resilience with ",_xlfn.IFS( AK18<=2500,"Very Weak", AK18<=5000,"Poor", AK18<=10000,"Challenging", AK18<=12500,"Border Line", AK18<=15000,"Improved", AK18<=20000,"Moderate", AK18<=25000,"Satisfactory", AK18<=30000,"Good", AK18<=35000,"Very Good", AK18<=40000,"High", AK18<=50000,"Excellent", AK18<=100000,"Superb", AK18>100000,"Superb" ), " Affordability.") -> Excellent Economic Resilience with Excellent Affordability. | AP18: We will assume the 5 socio economic sector spending will increase by 5% every year, Socio Ecnomic Sectors are Health, Housing, Energy and Education. Based on this assumption we will predict the value of Heart next year
A19: =_xlfn.CONCAT(UPPER(B19),"|",C19) -> USA|2024 | B19: USA | C19: 2024 | D19: 112600000000000 | E19: 0.054307116 | F19: 8161972572 | G19: 0.008896486 | H19: 29180000000000 | I19: 0.052669553 | J19: 340110988 | K19: 0.0098120423 | L19: 0.25914742 | M19: 3296240000000 | N19: 2093250000000 | O19: -1202990000000 | P19: -0.041226525 | Q19: 1.2153761 | R19: 0.015765235 | S19: 35464673929172 | T19: 0.055 | U19: 1950557066104 | V19: 0.066845684 | W19: 0.034 | X19: 85795.523 | Y19: 82878.475 | Z19: 0.943 | AA19: 0.0053304904 | AB19: 0.419 | AC19: 0.0023866348 | AD19: 0.524 | AE19: 0.1551075 | AF19: 0.1701075 | AG19: 0.0741075 | AH19: 0.0485075 | AI19: 0.44783 | AJ19: 0.59890522 | AK19: 43428.321 | AL19: A | AM19: 0.6A | AN19: =_xlfn.CONCAT(_xlfn.IFS( AJ19>=0.7,"Superb", AJ19>=0.51,"Excellent", AJ19>=0.41,"Good", AJ19>=0.31,"Satisfactory", AJ19>=0.26,"Moderate", AJ19>=0.1,"Weak", AJ19<0.1,"Very Weak" ), " Economic Resilience with ",_xlfn.IFS( AK19<=2500,"Very Weak", AK19<=5000,"Poor", AK19<=10000,"Challenging", AK19<=12500,"Border Line", AK19<=15000,"Improved", AK19<=20000,"Moderate", AK19<=25000,"Satisfactory", AK19<=30000,"Good", AK19<=35000,"Very Good", AK19<=40000,"High", AK19<=50000,"Excellent", AK19<=100000,"Superb", AK19>100000,"Superb" ), " Affordability.") -> Excellent Economic Resilience with Excellent Affordability. | AP19: We will assume the 5 socio economic sector spending will increase by 5% every year, Socio Ecnomic Sectors are Health, Housing, Energy and Education. Based on this assumption we will predict the value of Heart next year
A20: =_xlfn.CONCAT(UPPER(B20),"|",C20) -> USA|2025 | B20: USA | C20: 2025 | D20: 113795678000000 | E20: 0.01061881 | F20: 8231613070 | G20: 0.0085323122 | H20: 30507217000000 | I20: 0.04548379 | J20: 338000000 | K20: -0.0062067621 | L20: 0.26808766 | M20: 3393000000000 | N20: 2393000000000 | O20: -1000000000000 | P20: -0.032779129 | Q20: 1.1866045 | R20: -0.023673009 | S20: 36200000000000 | T20: 0.045 | U20: 1629000000000 | V20: 0.053397201 | W20: 0.0235 | X20: 90258.038 | Y20: 88136.975 | Z20: 0.948 | AA20: 0.0053022269 | AB20: 0.42 | AC20: 0.0023809524 | AD20: 0.528 | AE20: 0.161 | AF20: 0.176 | AG20: 0.08 | AH20: 0.0544 | AI20: 0.4714 | AJ20: 0.65331133 | AK20: 46536.323 | AL20: A | AM20: 0.65A | AN20: =_xlfn.CONCAT(_xlfn.IFS( AJ20>=0.7,"Superb", AJ20>=0.51,"Excellent", AJ20>=0.41,"Good", AJ20>=0.31,"Satisfactory", AJ20>=0.26,"Moderate", AJ20>=0.1,"Weak", AJ20<0.1,"Very Weak" ), " Economic Resilience with ",_xlfn.IFS( AK20<=2500,"Very Weak", AK20<=5000,"Poor", AK20<=10000,"Challenging", AK20<=12500,"Border Line", AK20<=15000,"Improved", AK20<=20000,"Moderate", AK20<=25000,"Satisfactory", AK20<=30000,"Good", AK20<=35000,"Very Good", AK20<=40000,"High", AK20<=50000,"Excellent", AK20<=100000,"Superb", AK20>100000,"Superb" ), " Affordability.") -> Excellent Economic Resilience with Excellent Affordability. | AO20: Biggest economy per GDP.Facing high debt/GDP and trade defecit challenges. Uncertain and unpredictable trade policies are inflationary and would put pressure on economic growth. Must reach economic normality quickly to fix US and global economy. | AP20: We will assume the 5 socio economic sector spending will increase by 5% every year, Socio Ecnomic Sectors are Health, Housing, Energy and Education. Based on this assumption we will predict the value of Heart next year
A21: =_xlfn.CONCAT(UPPER(B21),"|",C21) -> USA|2026 | B21: USA | C21: 2026 | D21: 120063810405112 | E21: 0.055082342 | F21: 8302201675 | G21: 0.0085753064 | H21: 32360367393707 | I21: 0.060744656 | J21: 3.402256e+08 | K21: 0.0065846118 | L21: 0.26952641 | M21: 3653795714286 | N21: 2469782857143 | O21: -1184012857143 | P21: -0.036588363 | Q21: 1.2213168 | R21: 0.029253536 | S21: 39522261786479 | T21: 0.061785714 | U21: 2441911174665 | V21: 0.075459934 | W21: 0.047714286 | X21: 95114.44 | Y21: 90576.123 | Z21: 0.94859293 | AA21: 0.00062545325 | AB21: 0.42085941 | AC21: 0.0020420451 | AD21: 0.52773352 | AE21: 0.1668925 | AF21: 0.1818925 | AG21: 0.0858925 | AH21: 0.0602925 | AI21: 0.49497 | AJ21: 0.65244811 | AK21: 47800.056 | AL21: A | AM21: 0.65A | AN21: =_xlfn.CONCAT(_xlfn.IFS( AJ21>=0.7,"Superb", AJ21>=0.51,"Excellent", AJ21>=0.41,"Good", AJ21>=0.31,"Satisfactory", AJ21>=0.26,"Moderate", AJ21>=0.1,"Weak", AJ21<0.1,"Very Weak" ), " Economic Resilience with ",_xlfn.IFS( AK21<=2500,"Very Weak", AK21<=5000,"Poor", AK21<=10000,"Challenging", AK21<=12500,"Border Line", AK21<=15000,"Improved", AK21<=20000,"Moderate", AK21<=25000,"Satisfactory", AK21<=30000,"Good", AK21<=35000,"Very Good", AK21<=40000,"High", AK21<=50000,"Excellent", AK21<=100000,"Superb", AK21>100000,"Superb" ), " Affordability.") -> Excellent Economic Resilience with Excellent Affordability. | AP21: We will assume the 5 socio economic sector spending will increase by 5% every year, Socio Ecnomic Sectors are Health, Housing, Energy and Education. Based on this assumption we will predict the value of Heart next year
A22: =_xlfn.CONCAT(UPPER(B22),"|",C22) -> USA|2027 | B22: USA | C22: 2027 | D22: 125735541889780 | E22: 0.047239309 | F22: 8372937901 | G22: 0.0085201769 | H22: 34173461630718 | I22: 0.056028234 | J22: 341986344 | K22: 0.0051752285 | L22: 0.2717884 | M22: 3825238928572 | N22: 2605921071429 | O22: -1219317857143 | P22: -0.035680256 | Q22: 1.2430331 | R22: 0.017781044 | S22: 42478745078487 | T22: 0.069821429 | U22: 2965926665302 | V22: 0.086790349 | W22: 0.050553571 | X22: 99926.392 | Y22: 94874.756 | Z22: 0.9507382 | AA22: 0.0022615245 | AB22: 0.42224361 | AC22: 0.0032781979 | AD22: 0.52849458 | AE22: 0.17307962 | AF22: 0.18807963 | AG22: 0.092079625 | AH22: 0.066479625 | AI22: 0.5197185 | AJ22: 0.66903629 | AK22: 50140.795 | AL22: A+ | AM22: 0.67A+ | AN22: =_xlfn.CONCAT(_xlfn.IFS( AJ22>=0.7,"Superb", AJ22>=0.51,"Excellent", AJ22>=0.41,"Good", AJ22>=0.31,"Satisfactory", AJ22>=0.26,"Moderate", AJ22>=0.1,"Weak", AJ22<0.1,"Very Weak" ), " Economic Resilience with ",_xlfn.IFS( AK22<=2500,"Very Weak", AK22<=5000,"Poor", AK22<=10000,"Challenging", AK22<=12500,"Border Line", AK22<=15000,"Improved", AK22<=20000,"Moderate", AK22<=25000,"Satisfactory", AK22<=30000,"Good", AK22<=35000,"Very Good", AK22<=40000,"High", AK22<=50000,"Excellent", AK22<=100000,"Superb", AK22>100000,"Superb" ), " Affordability.") -> Excellent Economic Resilience with Superb Affordability. | AP22: We will assume the 5 socio economic sector spending will increase by 5% every year, Socio Ecnomic Sectors are Health, Housing, Energy and Education. Based on this assumption we will predict the value of Heart next year
A23: =_xlfn.CONCAT(UPPER(B23),"|",C23) -> USA|2028 | B23: USA | C23: 2028 | D23: 131237442252096 | E23: 0.043757718 | F23: 8443822776 | G23: 0.0084659502 | H23: 35989111080848 | I23: 0.053130393 | J23: 3.4358954e+08 | K23: 0.0046878804 | L23: 0.27422899 | M23: 3996682142857 | N23: 2742059285714 | O23: -1254622857143 | P23: -0.034861179 | Q23: 1.2602965 | R23: 0.013888116 | S23: 45356951496476 | T23: 0.077857143 | U23: 3531362652226 | V23: 0.098123086 | W23: 0.053392857 | X23: 104744.49 | Y23: 99151.884 | Z23: 0.95341342 | AA23: 0.0028138365 | AB23: 0.42380656 | AC23: 0.0036878855 | AD23: 0.52960686 | AE23: 0.17957611 | AF23: 0.19457611 | AG23: 0.098576106 | AH23: 0.072976106 | AI23: 0.54570443 | AJ23: 0.68694915 | AK23: 52511.517 | AL23: A+ | AM23: 0.69A+ | AN23: =_xlfn.CONCAT(_xlfn.IFS( AJ23>=0.7,"Superb", AJ23>=0.51,"Excellent", AJ23>=0.41,"Good", AJ23>=0.31,"Satisfactory", AJ23>=0.26,"Moderate", AJ23>=0.1,"Weak", AJ23<0.1,"Very Weak" ), " Economic Resilience with ",_xlfn.IFS( AK23<=2500,"Very Weak", AK23<=5000,"Poor", AK23<=10000,"Challenging", AK23<=12500,"Border Line", AK23<=15000,"Improved", AK23<=20000,"Moderate", AK23<=25000,"Satisfactory", AK23<=30000,"Good", AK23<=35000,"Very Good", AK23<=40000,"High", AK23<=50000,"Excellent", AK23<=100000,"Superb", AK23>100000,"Superb" ), " Affordability.") -> Excellent Economic Resilience with Superb Affordability. | AP23: We will assume the 5 socio economic sector spending will increase by 5% every year, Socio Ecnomic Sectors are Health, Housing, Energy and Education. Based on this assumption we will predict the value of Heart next year
A24: =_xlfn.CONCAT(UPPER(B24),"|",C24) -> USA|2029 | B24: USA | C24: 2029 | D24: 136712479650225 | E24: 0.041718562 | F24: 8514849364 | G24: 0.0084116625 | H24: 37820753641775 | I24: 0.050894354 | J24: 3.451375e+08 | K24: 0.0045052869 | L24: 0.27664449 | M24: 4168125357143 | N24: 2878197500000 | O24: -1289927857143 | P24: -0.03410635 | Q24: 1.2759889 | R24: 0.012451305 | S24: 48258860210723 | T24: 0.085892857 | U24: 4145091385957 | V24: 0.10959833 | W24: 0.056232143 | X24: 109581.7 | Y24: 103419.68 | Z24: 0.95627833 | AA24: 0.0030048995 | AB24: 0.42543341 | AC24: 0.0038239694 | AD24: 0.53084492 | AE24: 0.18639741 | AF24: 0.20139741 | AG24: 0.10539741 | AH24: 0.079797412 | AI24: 0.57298965 | AJ24: 0.70592945 | AK24: 54899.814 | AL24: A+ | AM24: 0.71A+ | AN24: =_xlfn.CONCAT(_xlfn.IFS( AJ24>=0.7,"Superb", AJ24>=0.51,"Excellent", AJ24>=0.41,"Good", AJ24>=0.31,"Satisfactory", AJ24>=0.26,"Moderate", AJ24>=0.1,"Weak", AJ24<0.1,"Very Weak" ), " Economic Resilience with ",_xlfn.IFS( AK24<=2500,"Very Weak", AK24<=5000,"Poor", AK24<=10000,"Challenging", AK24<=12500,"Border Line", AK24<=15000,"Improved", AK24<=20000,"Moderate", AK24<=25000,"Satisfactory", AK24<=30000,"Good", AK24<=35000,"Very Good", AK24<=40000,"High", AK24<=50000,"Excellent", AK24<=100000,"Superb", AK24>100000,"Superb" ), " Affordability.") -> Superb Economic Resilience with Superb Affordability. | AP24: We will assume the 5 socio economic sector spending will increase by 5% every year, Socio Ecnomic Sectors are Health, Housing, Energy and Education. Based on this assumption we will predict the value of Heart next year
A25: =_xlfn.CONCAT(UPPER(B25),"|",C25) -> USA|2030 | B25: USA | C25: 2030 | D25: 141834754671550 | F25: 8586617399 | H25: 39740172889890 | J25: 3.4676317e+08 | L25: 0.28018643 | M25: 4339568571429 | N25: 3014335714286 | O25: -1325232857143 | P25: -0.033347436 | Q25: 1.291128 | S25: 51309650444299 | T25: 0.093928571 | U25: 4819442166733 | V25: 0.12127381 | W25: 0.059071429 | X25: 114603.21 | Y25: 107833.44 | Z25: 0.95921414 | AB25: 0.42708417 | AD25: 0.53212997 | AE25: 0.19355978 | AF25: 0.20855978 | AG25: 0.11255978 | AH25: 0.086959782 | AI25: 0.60163913 | AJ25: 0.72720431 | AK25: 57381.403 | AL25: A+ | AM25: 0.73A+ | AN25: =_xlfn.CONCAT(_xlfn.IFS( AJ25>=0.7,"Superb", AJ25>=0.51,"Excellent", AJ25>=0.41,"Good", AJ25>=0.31,"Satisfactory", AJ25>=0.26,"Moderate", AJ25>=0.1,"Weak", AJ25<0.1,"Very Weak" ), " Economic Resilience with ",_xlfn.IFS( AK25<=2500,"Very Weak", AK25<=5000,"Poor", AK25<=10000,"Challenging", AK25<=12500,"Border Line", AK25<=15000,"Improved", AK25<=20000,"Moderate", AK25<=25000,"Satisfactory", AK25<=30000,"Good", AK25<=35000,"Very Good", AK25<=40000,"High", AK25<=50000,"Excellent", AK25<=100000,"Superb", AK25>100000,"Superb" ), " Affordability.") -> Superb Economic Resilience with Superb Affordability. | AP25: We will assume the 5 socio economic sector spending will increase by 5% every year, Socio Ecnomic Sectors are Health, Housing, Energy and Education. Based on this assumption we will predict the value of Heart next year
A26: =_xlfn.CONCAT(UPPER(B26),"|",C26) -> UNITED KINGDOM|2019 | B26: United Kingdom | C26: 2019 | D26: 87700000000000 | F26: 7810000000 | H26: 2880000000000 | J26: 66631000 | L26: 0.032839225 | M26: 745700000000 | N26: 718800000000 | O26: -26900000000 | P26: -0.0093402778 | Q26: 0.796 | S26: 2292480000000 | T26: 0.0075 | U26: 17193600000 | V26: 0.00597 | W26: 0.017 | X26: 43223.124 | Y26: 42488.331 | Z26: 0.92 | AB26: 0.36 | AD26: 0.56 | AE26: 0.15337673 | AF26: 0.084376735 | AG26: 0.043376735 | AH26: 0.014376735 | AI26: 0.29550694 | AJ26: 0.31303589 | AK26: 23793.465 | AL26: B- | AM26: 0.31B- | AN26: =_xlfn.CONCAT(_xlfn.IFS( AJ26>=0.7,"Superb", AJ26>=0.51,"Excellent", AJ26>=0.41,"Good", AJ26>=0.31,"Satisfactory", AJ26>=0.26,"Moderate", AJ26>=0.1,"Weak", AJ26<0.1,"Very Weak" ), " Economic Resilience with ",_xlfn.IFS( AK26<=2500,"Very Weak", AK26<=5000,"Poor", AK26<=10000,"Challenging", AK26<=12500,"Border Line", AK26<=15000,"Improved", AK26<=20000,"Moderate", AK26<=25000,"Satisfactory", AK26<=30000,"Good", AK26<=35000,"Very Good", AK26<=40000,"High", AK26<=50000,"Excellent", AK26<=100000,"Superb", AK26>100000,"Superb" ), " Affordability.") -> Satisfactory Economic Resilience with Satisfactory Affordability. | AP26: We will assume the 5 socio economic sector spending will increase by 5% every year, Socio Ecnomic Sectors are Health, Housing, Energy and Education. Based on this assumption we will predict the value of Heart next year
A27: =_xlfn.CONCAT(UPPER(B27),"|",C27) -> UNITED KINGDOM|2020 | B27: United Kingdom | C27: 2020 | D27: 84750000000000 | E27: -0.0336374 | F27: 7890000000 | G27: 0.010243278 | H27: 2720000000000 | I27: -0.055555556 | J27: 66744000 | K27: 0.0016959073 | L27: 0.032094395 | M27: 620700000000 | N27: 636000000000 | O27: 15300000000 | P27: 0.005625 | Q27: 0.845 | R27: 0.061557789 | S27: 2298400000000 | T27: 0.001 | U27: 2298400000 | V27: 0.000845 | W27: 0.01 | X27: 40752.727 | Y27: 40345.2 | Z27: 0.93 | AA27: 0.010869565 | AB27: 0.354 | AC27: -0.016949153 | AD27: 0.576 | AE27: 0.15726498 | AF27: 0.088264984 | AG27: 0.047264984 | AH27: 0.018264984 | AI27: 0.31105994 | AJ27: 0.34793433 | AK27: 23238.835 | AL27: B- | AM27: 0.35B- | AN27: =_xlfn.CONCAT(_xlfn.IFS( AJ27>=0.7,"Superb", AJ27>=0.51,"Excellent", AJ27>=0.41,"Good", AJ27>=0.31,"Satisfactory", AJ27>=0.26,"Moderate", AJ27>=0.1,"Weak", AJ27<0.1,"Very Weak" ), " Economic Resilience with ",_xlfn.IFS( AK27<=2500,"Very Weak", AK27<=5000,"Poor", AK27<=10000,"Challenging", AK27<=12500,"Border Line", AK27<=15000,"Improved", AK27<=20000,"Moderate", AK27<=25000,"Satisfactory", AK27<=30000,"Good", AK27<=35000,"Very Good", AK27<=40000,"High", AK27<=50000,"Excellent", AK27<=100000,"Superb", AK27>100000,"Superb" ), " Affordability.") -> Satisfactory Economic Resilience with Satisfactory Affordability. | AP27: We will assume the 5 socio economic sector spending will increase by 5% every year, Socio Ecnomic Sectors are Health, Housing, Energy and Education. Based on this assumption we will predict the value of Heart next year
A28: =_xlfn.CONCAT(UPPER(B28),"|",C28) -> UNITED KINGDOM|2021 | B28: United Kingdom | C28: 2021 | D28: 96140000000000 | E28: 0.13439528 | F28: 7950000000 | G28: 0.0076045627 | H28: 3190000000000 | I28: 0.17279412 | J28: 66984000 | K28: 0.0035958288 | L28: 0.033180778 | M28: 679400000000 | N28: 680300000000 | O28: 900000000 | P28: 0.00028213166 | Q28: 0.954 | R28: 0.12899408 | S28: 3043260000000 | T28: 0.0025 | U28: 7608150000 | V28: 0.002385 | W28: 0.025 | X28: 47623.313 | Y28: 46432.73 | Z28: 0.92 | AA28: -0.010752688 | AB28: 0.344 | AC28: -0.029069767 | AD28: 0.576 | AE28: 0.16135788 | AF28: 0.092357878 | AG28: 0.051357878 | AH28: 0.022357878 | AI28: 0.32743151 | AJ28: 0.35850942 | AK28: 26745.253 | AL28: B | AM28: 0.36B | AN28: =_xlfn.CONCAT(_xlfn.IFS( AJ28>=0.7,"Superb", AJ28>=0.51,"Excellent", AJ28>=0.41,"Good", AJ28>=0.31,"Satisfactory", AJ28>=0.26,"Moderate", AJ28>=0.1,"Weak", AJ28<0.1,"Very Weak" ), " Economic Resilience with ",_xlfn.IFS( AK28<=2500,"Very Weak", AK28<=5000,"Poor", AK28<=10000,"Challenging", AK28<=12500,"Border Line", AK28<=15000,"Improved", AK28<=20000,"Moderate", AK28<=25000,"Satisfactory", AK28<=30000,"Good", AK28<=35000,"Very Good", AK28<=40000,"High", AK28<=50000,"Excellent", AK28<=100000,"Superb", AK28>100000,"Superb" ), " Affordability.") -> Satisfactory Economic Resilience with Good Affordability. | AP28: We will assume the 5 socio economic sector spending will increase by 5% every year, Socio Ecnomic Sectors are Health, Housing, Energy and Education. Based on this assumption we will predict the value of Heart next year
A29: =_xlfn.CONCAT(UPPER(B29),"|",C29) -> UNITED KINGDOM|2022 | B29: United Kingdom | C29: 2022 | D29: 101560000000000 | E29: 0.056376118 | F29: 8020000000 | G29: 0.0088050314 | H29: 3180000000000 | I29: -0.0031347962 | J29: 67604000 | K29: 0.0092559417 | L29: 0.03131154 | M29: 906900000000 | N29: 879100000000 | O29: -27800000000 | P29: -0.0087421384 | Q29: 0.943 | R29: -0.011530398 | S29: 2998740000000 | T29: 0.01 | U29: 29987400000 | V29: 0.00943 | W29: 0.079 | X29: 47038.637 | Y29: 43322.584 | Z29: 0.94 | AA29: 0.02173913 | AB29: 0.355 | AC29: 0.030985915 | AD29: 0.585 | AE29: 0.16566619 | AF29: 0.096666188 | AG29: 0.055666187 | AH29: 0.026666188 | AI29: 0.34466475 | AJ29: 0.35780415 | AK29: 25343.712 | AL29: B | AM29: 0.36B | AN29: =_xlfn.CONCAT(_xlfn.IFS( AJ29>=0.7,"Superb", AJ29>=0.51,"Excellent", AJ29>=0.41,"Good", AJ29>=0.31,"Satisfactory", AJ29>=0.26,"Moderate", AJ29>=0.1,"Weak", AJ29<0.1,"Very Weak" ), " Economic Resilience with ",_xlfn.IFS( AK29<=2500,"Very Weak", AK29<=5000,"Poor", AK29<=10000,"Challenging", AK29<=12500,"Border Line", AK29<=15000,"Improved", AK29<=20000,"Moderate", AK29<=25000,"Satisfactory", AK29<=30000,"Good", AK29<=35000,"Very Good", AK29<=40000,"High", AK29<=50000,"Excellent", AK29<=100000,"Superb", AK29>100000,"Superb" ), " Affordability.") -> Satisfactory Economic Resilience with Good Affordability. | AP29: We will assume the 5 socio economic sector spending will increase by 5% every year, Socio Ecnomic Sectors are Health, Housing, Energy and Education. Based on this assumption we will predict the value of Heart next year
A30: =_xlfn.CONCAT(UPPER(B30),"|",C30) -> UNITED KINGDOM|2023 | B30: United Kingdom | C30: 2023 | D30: 106800000000000 | E30: 0.051595116 | F30: 8090000000 | G30: 0.0087281796 | H30: 3420000000000 | I30: 0.075471698 | J30: 68492000 | K30: 0.013135317 | L30: 0.032022472 | M30: 910400000000 | N30: 878300000000 | O30: -32100000000 | P30: -0.0093859649 | Q30: 0.932 | R30: -0.011664899 | S30: 3187440000000 | T30: 0.045 | U30: 143434800000 | V30: 0.04194 | W30: 0.068 | X30: 49932.839 | Y30: 46537.406 | Z30: 0.95 | AA30: 0.010638298 | AB30: 0.331 | AC30: -0.072507553 | AD30: 0.619 | AE30: 0.17020125 | AF30: 0.10120125 | AG30: 0.06020125 | AH30: 0.03120125 | AI30: 0.362805 | AJ30: 0.34350151 | AK30: 28806.654 | AL30: B | AM30: 0.34B | AN30: =_xlfn.CONCAT(_xlfn.IFS( AJ30>=0.7,"Superb", AJ30>=0.51,"Excellent", AJ30>=0.41,"Good", AJ30>=0.31,"Satisfactory", AJ30>=0.26,"Moderate", AJ30>=0.1,"Weak", AJ30<0.1,"Very Weak" ), " Economic Resilience with ",_xlfn.IFS( AK30<=2500,"Very Weak", AK30<=5000,"Poor", AK30<=10000,"Challenging", AK30<=12500,"Border Line", AK30<=15000,"Improved", AK30<=20000,"Moderate", AK30<=25000,"Satisfactory", AK30<=30000,"Good", AK30<=35000,"Very Good", AK30<=40000,"High", AK30<=50000,"Excellent", AK30<=100000,"Superb", AK30>100000,"Superb" ), " Affordability.") -> Satisfactory Economic Resilience with Good Affordability. | AP30: We will assume the 5 socio economic sector spending will increase by 5% every year, Socio Ecnomic Sectors are Health, Housing, Energy and Education. Based on this assumption we will predict the value of Heart next year
A31: =_xlfn.CONCAT(UPPER(B31),"|",C31) -> UNITED KINGDOM|2024 | B31: United Kingdom | C31: 2024 | D31: 112600000000000 | E31: 0.054307116 | F31: 8161972572 | G31: 0.008896486 | H31: 3686033040000 | I31: 0.077787439 | J31: 69226000 | K31: 0.01071658 | L31: 0.03273564 | M31: 918700000000 | N31: 893200000000 | O31: -25500000000 | P31: -0.0069180064 | Q31: 0.944 | R31: 0.012875536 | S31: 3479615189760 | T31: 0.05 | U31: 173980759488 | V31: 0.0472 | W31: 0.033 | X31: 53246.368 | Y31: 51489.237 | Z31: 0.948 | AA31: -0.0021052632 | AB31: 0.329 | AC31: -0.0060790274 | AD31: 0.619 | AE31: 0.174975 | AF31: 0.105975 | AG31: 0.064975 | AH31: 0.035975 | AI31: 0.3819 | AJ31: 0.36051763 | AK31: 31871.838 | AL31: B+ | AM31: 0.36B+ | AN31: =_xlfn.CONCAT(_xlfn.IFS( AJ31>=0.7,"Superb", AJ31>=0.51,"Excellent", AJ31>=0.41,"Good", AJ31>=0.31,"Satisfactory", AJ31>=0.26,"Moderate", AJ31>=0.1,"Weak", AJ31<0.1,"Very Weak" ), " Economic Resilience with ",_xlfn.IFS( AK31<=2500,"Very Weak", AK31<=5000,"Poor", AK31<=10000,"Challenging", AK31<=12500,"Border Line", AK31<=15000,"Improved", AK31<=20000,"Moderate", AK31<=25000,"Satisfactory", AK31<=30000,"Good", AK31<=35000,"Very Good", AK31<=40000,"High", AK31<=50000,"Excellent", AK31<=100000,"Superb", AK31>100000,"Superb" ), " Affordability.") -> Satisfactory Economic Resilience with Very Good Affordability. | AP31: We will assume the 5 socio economic sector spending will increase by 5% every year, Socio Ecnomic Sectors are Health, Housing, Energy and Education. Based on this assumption we will predict the value of Heart next year
A32: =_xlfn.CONCAT(UPPER(B32),"|",C32) -> UNITED KINGDOM|2025 | B32: United Kingdom | C32: 2025 | D32: 113795678000000 | E32: 0.01061881 | F32: 8231613070 | G32: 0.0085323122 | H32: 3839000000000 | I32: 0.041499075 | J32: 68300000 | K32: -0.013376477 | L32: 0.033735903 | M32: 959400000000 | N32: 928900000000 | O32: -30500000000 | P32: -0.0079447773 | Q32: 0.96 | R32: 0.016949153 | S32: 3685440000000 | T32: 0.0425 | U32: 156631200000 | V32: 0.0408 | W32: 0.034 | X32: 56207.906 | Y32: 54296.837 | Z32: 0.946 | AA32: -0.0021097046 | AB32: 0.354 | AC32: 0.070621469 | AD32: 0.592 | AE32: 0.18 | AF32: 0.111 | AG32: 0.07 | AH32: 0.041 | AI32: 0.402 | AJ32: 0.38699113 | AK32: 32143.728 | AL32: B+ | AM32: 0.39B+ | AN32: =_xlfn.CONCAT(_xlfn.IFS( AJ32>=0.7,"Superb", AJ32>=0.51,"Excellent", AJ32>=0.41,"Good", AJ32>=0.31,"Satisfactory", AJ32>=0.26,"Moderate", AJ32>=0.1,"Weak", AJ32<0.1,"Very Weak" ), " Economic Resilience with ",_xlfn.IFS( AK32<=2500,"Very Weak", AK32<=5000,"Poor", AK32<=10000,"Challenging", AK32<=12500,"Border Line", AK32<=15000,"Improved", AK32<=20000,"Moderate", AK32<=25000,"Satisfactory", AK32<=30000,"Good", AK32<=35000,"Very Good", AK32<=40000,"High", AK32<=50000,"Excellent", AK32<=100000,"Superb", AK32>100000,"Superb" ), " Affordability.") -> Satisfactory Economic Resilience with Very Good Affordability. | AO32: 6th largest per GDP. Facing economic growth and US tarrifs challenges.Political decision leaving EU did not go well economically as it restricted market access.Economic diversification needed. | AP32: We will assume the 5 socio economic sector spending will increase by 5% every year, Socio Ecnomic Sectors are Health, Housing, Energy and Education. Based on this assumption we will predict the value of Heart next year
A33: =_xlfn.CONCAT(UPPER(B33),"|",C33) -> UNITED KINGDOM|2026 | B33: United Kingdom | C33: 2026 | D33: 120063810405112 | E33: 0.055082342 | F33: 8302201675 | G33: 0.0085753064 | H33: 4015031459899 | I33: 0.045853467 | J33: 68968137 | K33: 0.0097823927 | L33: 0.033440813 | M33: 1029900000000 | N33: 993900000000 | O33: -36000000000 | P33: -0.0089663058 | Q33: 0.9987745 | R33: 0.040390105 | S33: 4010111043094 | T33: 0.057714286 | U33: 231440694487 | V33: 0.057643557 | W33: 0.058 | X33: 58215.744 | Y33: 54839.231 | Z33: 0.95365793 | AA33: 0.0080950591 | AB33: 0.34389298 | AC33: -0.029390003 | AD33: 0.60976494 | AE33: 0.185025 | AF33: 0.116025 | AG33: 0.075025 | AH33: 0.046025 | AI33: 0.4221 | AJ33: 0.38893095 | AK33: 33439.041 | AL33: B+ | AM33: 0.39B+ | AN33: =_xlfn.CONCAT(_xlfn.IFS( AJ33>=0.7,"Superb", AJ33>=0.51,"Excellent", AJ33>=0.41,"Good", AJ33>=0.31,"Satisfactory", AJ33>=0.26,"Moderate", AJ33>=0.1,"Weak", AJ33<0.1,"Very Weak" ), " Economic Resilience with ",_xlfn.IFS( AK33<=2500,"Very Weak", AK33<=5000,"Poor", AK33<=10000,"Challenging", AK33<=12500,"Border Line", AK33<=15000,"Improved", AK33<=20000,"Moderate", AK33<=25000,"Satisfactory", AK33<=30000,"Good", AK33<=35000,"Very Good", AK33<=40000,"High", AK33<=50000,"Excellent", AK33<=100000,"Superb", AK33>100000,"Superb" ), " Affordability.") -> Satisfactory Economic Resilience with Very Good Affordability. | AP33: We will assume the 5 socio economic sector spending will increase by 5% every year, Socio Ecnomic Sectors are Health, Housing, Energy and Education. Based on this assumption we will predict the value of Heart next year
A34: =_xlfn.CONCAT(UPPER(B34),"|",C34) -> UNITED KINGDOM|2027 | B34: United Kingdom | C34: 2027 | D34: 125735541889780 | E34: 0.047239309 | F34: 8372937901 | G34: 0.0085201769 | H34: 4201345719753 | I34: 0.046404184 | J34: 69440404 | K34: 0.0068476123 | L34: 0.033414146 | M34: 1082332142857 | N34: 1041853571429 | O34: -40478571429 | P34: -0.0096346681 | Q34: 1.029458 | R34: 0.030721182 | S34: 4325109107856 | T34: 0.066482143 | U34: 287542521581 | V34: 0.068440576 | W34: 0.063 | X34: 60502.898 | Y34: 56691.216 | Z34: 0.95950693 | AA34: 0.0061332258 | AB34: 0.33897217 | AC34: -0.014516858 | AD34: 0.62053475 | AE34: 0.19030125 | AF34: 0.12130125 | AG34: 0.08030125 | AH34: 0.05130125 | AI34: 0.443205 | AJ34: 0.3985439 | AK34: 35178.869 | AL34: A- | AM34: 0.4A- | AN34: =_xlfn.CONCAT(_xlfn.IFS( AJ34>=0.7,"Superb", AJ34>=0.51,"Excellent", AJ34>=0.41,"Good", AJ34>=0.31,"Satisfactory", AJ34>=0.26,"Moderate", AJ34>=0.1,"Weak", AJ34<0.1,"Very Weak" ), " Economic Resilience with ",_xlfn.IFS( AK34<=2500,"Very Weak", AK34<=5000,"Poor", AK34<=10000,"Challenging", AK34<=12500,"Border Line", AK34<=15000,"Improved", AK34<=20000,"Moderate", AK34<=25000,"Satisfactory", AK34<=30000,"Good", AK34<=35000,"Very Good", AK34<=40000,"High", AK34<=50000,"Excellent", AK34<=100000,"Superb", AK34>100000,"Superb" ), " Affordability.") -> Satisfactory Economic Resilience with High Affordability. | AP34: We will assume the 5 socio economic sector spending will increase by 5% every year, Socio Ecnomic Sectors are Health, Housing, Energy and Education. Based on this assumption we will predict the value of Heart next year
A35: =_xlfn.CONCAT(UPPER(B35),"|",C35) -> UNITED KINGDOM|2028 | B35: United Kingdom | C35: 2028 | D35: 131237442252096 | E35: 0.043757718 | F35: 8443822776 | G35: 0.0084659502 | H35: 4392794551938 | I35: 0.045568455 | J35: 69846120 | K35: 0.0058426468 | L35: 0.033472113 | M35: 1134764285714 | N35: 1089807142857 | O35: -44957142857 | P35: -0.010234292 | Q35: 1.0574551 | R35: 0.027195937 | S35: 4645183049143 | T35: 0.07525 | U35: 349550024448 | V35: 0.079573497 | W35: 0.068 | X35: 62892.463 | Y35: 58615.776 | Z35: 0.96474239 | AA35: 0.005456407 | AB35: 0.33582093 | AC35: -0.0093837146 | AD35: 0.62892146 | AE35: 0.19584131 | AF35: 0.12684131 | AG35: 0.085841313 | AH35: 0.056841312 | AI35: 0.46536525 | AJ35: 0.40902957 | AK35: 36864.719 | AL35: A- | AM35: 0.41A- | AN35: =_xlfn.CONCAT(_xlfn.IFS( AJ35>=0.7,"Superb", AJ35>=0.51,"Excellent", AJ35>=0.41,"Good", AJ35>=0.31,"Satisfactory", AJ35>=0.26,"Moderate", AJ35>=0.1,"Weak", AJ35<0.1,"Very Weak" ), " Economic Resilience with ",_xlfn.IFS( AK35<=2500,"Very Weak", AK35<=5000,"Poor", AK35<=10000,"Challenging", AK35<=12500,"Border Line", AK35<=15000,"Improved", AK35<=20000,"Moderate", AK35<=25000,"Satisfactory", AK35<=30000,"Good", AK35<=35000,"Very Good", AK35<=40000,"High", AK35<=50000,"Excellent", AK35<=100000,"Superb", AK35>100000,"Superb" ), " Affordability.") -> Satisfactory Economic Resilience with High Affordability. | AP35: We will assume the 5 socio economic sector spending will increase by 5% every year, Socio Ecnomic Sectors are Health, Housing, Energy and Education. Based on this assumption we will predict the value of Heart next year
A36: =_xlfn.CONCAT(UPPER(B36),"|",C36) -> UNITED KINGDOM|2029 | B36: United Kingdom | C36: 2029 | D36: 136712479650225 | E36: 0.041718562 | F36: 8514849364 | G36: 0.0084116625 | H36: 4587498480202 | I36: 0.044323477 | J36: 70228370 | K36: 0.0054727353 | L36: 0.033555814 | M36: 1187196428571 | N36: 1137760714286 | O36: -49435714286 | P36: -0.010776181 | Q36: 1.0845907 | R36: 0.025661248 | S36: 4975558318685 | T36: 0.084017857 | U36: 418035748025 | V36: 0.091124989 | W36: 0.073 | X36: 65322.583 | Y36: 60554.034 | Z36: 0.9697626 | AA36: 0.0052036832 | AB36: 0.33329911 | AC36: -0.0075662193 | AD36: 0.63646349 | AE36: 0.20165838 | AF36: 0.13265838 | AG36: 0.091658378 | AH36: 0.062658378 | AI36: 0.48863351 | AJ36: 0.42028816 | AK36: 38540.432 | AL36: A- | AM36: 0.42A- | AN36: =_xlfn.CONCAT(_xlfn.IFS( AJ36>=0.7,"Superb", AJ36>=0.51,"Excellent", AJ36>=0.41,"Good", AJ36>=0.31,"Satisfactory", AJ36>=0.26,"Moderate", AJ36>=0.1,"Weak", AJ36<0.1,"Very Weak" ), " Economic Resilience with ",_xlfn.IFS( AK36<=2500,"Very Weak", AK36<=5000,"Poor", AK36<=10000,"Challenging", AK36<=12500,"Border Line", AK36<=15000,"Improved", AK36<=20000,"Moderate", AK36<=25000,"Satisfactory", AK36<=30000,"Good", AK36<=35000,"Very Good", AK36<=40000,"High", AK36<=50000,"Excellent", AK36<=100000,"Superb", AK36>100000,"Superb" ), " Affordability.") -> Good Economic Resilience with High Affordability. | AP36: We will assume the 5 socio economic sector spending will increase by 5% every year, Socio Ecnomic Sectors are Health, Housing, Energy and Education. Based on this assumption we will predict the value of Heart next year
A37: =_xlfn.CONCAT(UPPER(B37),"|",C37) -> UNITED KINGDOM|2030 | B37: United Kingdom | C37: 2030 | D37: 141834754671550 | F37: 8586617399 | H37: 4781569921881 | J37: 70606569 | L37: 0.033712259 | M37: 1239628571429 | N37: 1185714285714 | O37: -53914285714 | P37: -0.011275436 | Q37: 1.1115065 | S37: 5314745903260 | T37: 0.092785714 | U37: 493132494881 | V37: 0.10313192 | W37: 0.078 | X37: 67721.318 | Y37: 62439.055 | Z37: 0.97470664 | AB37: 0.33101004 | AD37: 0.6436966 | AE37: 0.2077663 | AF37: 0.1387663 | AG37: 0.097766297 | AH37: 0.068766297 | AI37: 0.51306519 | AJ37: 0.43237009 | AK37: 40191.808 | AL37: A | AM37: 0.43A | AN37: =_xlfn.CONCAT(_xlfn.IFS( AJ37>=0.7,"Superb", AJ37>=0.51,"Excellent", AJ37>=0.41,"Good", AJ37>=0.31,"Satisfactory", AJ37>=0.26,"Moderate", AJ37>=0.1,"Weak", AJ37<0.1,"Very Weak" ), " Economic Resilience with ",_xlfn.IFS( AK37<=2500,"Very Weak", AK37<=5000,"Poor", AK37<=10000,"Challenging", AK37<=12500,"Border Line", AK37<=15000,"Improved", AK37<=20000,"Moderate", AK37<=25000,"Satisfactory", AK37<=30000,"Good", AK37<=35000,"Very Good", AK37<=40000,"High", AK37<=50000,"Excellent", AK37<=100000,"Superb", AK37>100000,"Superb" ), " Affordability.") -> Good Economic Resilience with Excellent Affordability. | AP37: We will assume the 5 socio economic sector spending will increase by 5% every year, Socio Ecnomic Sectors are Health, Housing, Energy and Education. Based on this assumption we will predict the value of Heart next year
A38: =_xlfn.CONCAT(UPPER(B38),"|",C38) -> JAPAN|2019 | B38: Japan | C38: 2019 | D38: 87700000000000 | F38: 7810000000 | H38: 5120000000000 | J38: 126633000 | L38: 0.058380844 | M38: 908590000000 | N38: 893780000000 | O38: -14810000000 | P38: -0.0028925781 | Q38: 1.9746 | S38: 10109952000000 | T38: -0.001 | U38: -10109952000 | V38: -0.0019746 | W38: 0.005 | X38: 40431.799 | Y38: 40229.64 | Z38: 0.918 | AB38: 0.33 | AD38: 0.588 | AE38: 0.084436367 | AF38: 0.094436367 | AG38: 0.077436367 | AH38: 0.027436367 | AI38: 0.28374547 | AJ38: 0.34120834 | AK38: 23655.028 | AL38: B- | AM38: 0.34B- | AN38: =_xlfn.CONCAT(_xlfn.IFS( AJ38>=0.7,"Superb", AJ38>=0.51,"Excellent", AJ38>=0.41,"Good", AJ38>=0.31,"Satisfactory", AJ38>=0.26,"Moderate", AJ38>=0.1,"Weak", AJ38<0.1,"Very Weak" ), " Economic Resilience with ",_xlfn.IFS( AK38<=2500,"Very Weak", AK38<=5000,"Poor", AK38<=10000,"Challenging", AK38<=12500,"Border Line", AK38<=15000,"Improved", AK38<=20000,"Moderate", AK38<=25000,"Satisfactory", AK38<=30000,"Good", AK38<=35000,"Very Good", AK38<=40000,"High", AK38<=50000,"Excellent", AK38<=100000,"Superb", AK38>100000,"Superb" ), " Affordability.") -> Satisfactory Economic Resilience with Satisfactory Affordability. | AP38: We will assume the 5 socio economic sector spending will increase by 5% every year, Socio Ecnomic Sectors are Health, Housing, Energy and Education. Based on this assumption we will predict the value of Heart next year
